Workbook
Name ClientNameList: OFFSET('Clients List'!$A$2,0,0,COUNTA('Clients List'!$A:$A)-1,1)
Name LessonTypeList: ValidationLists!$A$1:$A$14
Name Package_Semi_Lesson__125: 'Clients List'!$B$6

Sheet Clients List
A1: Client Name | B1: Lesson Type | C1: Package Date | D1: Package Size | E1: Package Balance | F1: Price per Lesson | G1: Email | H1: Phone Number
E2: =IF(OR(D2="",D2=0),"",D2-SUMIFS('Lessons Log'!$E:$E,'Lessons Log'!$C:$C,A2,'Lessons Log'!$D:$D,"*Package*"))
E3: =IF(OR(D3="",D3=0),"",D3-SUMIFS('Lessons Log'!$E:$E,'Lessons Log'!$C:$C,A3,'Lessons Log'!$D:$D,"*Package*"))
E4: =IF(OR(D4="",D4=0),"",D4-SUMIFS('Lessons Log'!$E:$E,'Lessons Log'!$C:$C,A4,'Lessons Log'!$D:$D,"*Package*"))
E5: =IF(OR(D5="",D5=0),"",D5-SUMIFS('Lessons Log'!$E:$E,'Lessons Log'!$C:$C,A5,'Lessons Log'!$D:$D,"*Package*"))
E6: =IF(OR(D6="",D6=0),"",D6-SUMIFS('Lessons Log'!$E:$E,'Lessons Log'!$C:$C,A6,'Lessons Log'!$D:$D,"*Package*"))
E7: =IF(OR(D7="",D7=0),"",D7-SUMIFS('Lessons Log'!$E:$E,'Lessons Log'!$C:$C,A7,'Lessons Log'!$D:$D,"*Package*"))
B8: =IFERROR(INDEX([1]Clients!$D:$D, MATCH(A8, [1]Clients!$A:$A, 0)), "") | E8: =IF(OR(D8="",D8=0),"",D8-SUMIFS('Lessons Log'!$E:$E,'Lessons Log'!$C:$C,A8,'Lessons Log'!$D:$D,"*Package*"))
B9: =IFERROR(INDEX([1]Clients!$D:$D, MATCH(A9, [1]Clients!$A:$A, 0)), "") | E9: =IF(OR(D9="",D9=0),"",D9-SUMIFS('Lessons Log'!$E:$E,'Lessons Log'!$C:$C,A9,'Lessons Log'!$D:$D,"*Package*"))
B10: =IFERROR(INDEX([1]Clients!$D:$D, MATCH(A10, [1]Clients!$A:$A, 0)), "") | E10: =IF(OR(D10="",D10=0),"",D10-SUMIFS('Lessons Log'!$E:$E,'Lessons Log'!$C:$C,A10,'Lessons Log'!$D:$D,"*Package*"))
B11: =IFERROR(INDEX([1]Clients!$D:$D, MATCH(A11, [1]Clients!$A:$A, 0)), "") | E11: =IF(OR(D11="",D11=0),"",D11-SUMIFS('Lessons Log'!$E:$E,'Lessons Log'!$C:$C,A11,'Lessons Log'!$D:$D,"*Package*")) | F11: =IFERROR(INDEX([1]Clients!F:F, MATCH(A11, [1]Clients!A:A, 0)), "")
B12: =IFERROR(INDEX([1]Clients!$D:$D, MATCH(A12, [1]Clients!$A:$A, 0)), "") | E12: =IF(OR(D12="",D12=0),"",D12-SUMIFS('Lessons Log'!$E:$E,'Lessons Log'!$C:$C,A12,'Lessons Log'!$D:$D,"*Package*")) | F12: =IFERROR(INDEX([1]Clients!F:F, MATCH(A12, [1]Clients!A:A, 0)), "")
B13: =IFERROR(INDEX([1]Clients!$D:$D, MATCH(A13, [1]Clients!$A:$A, 0)), "") | E13: =IF(OR(D13="",D13=0),"",D13-SUMIFS('Lessons Log'!$E:$E,'Lessons Log'!$C:$C,A13,'Lessons Log'!$D:$D,"*Package*")) | F13: =IFERROR(INDEX([1]Clients!F:F, MATCH(A13, [1]Clients!A:A, 0)), "")
B14: =IFERROR(INDEX([1]Clients!$D:$D, MATCH(A14, [1]Clients!$A:$A, 0)), "") | E14: =IF(OR(D14="",D14=0),"",D14-SUMIFS('Lessons Log'!$E:$E,'Lessons Log'!$C:$C,A14,'Lessons Log'!$D:$D,"*Package*")) | F14: =IFERROR(INDEX([1]Clients!F:F, MATCH(A14, [1]Clients!A:A, 0)), "")
B15: =IFERROR(INDEX([1]Clients!$D:$D, MATCH(A15, [1]Clients!$A:$A, 0)), "") | E15: =IF(OR(D15="",D15=0),"",D15-SUMIFS('Lessons Log'!$E:$E,'Lessons Log'!$C:$C,A15,'Lessons Log'!$D:$D,"*Package*")) | F15: =IFERROR(INDEX([1]Clients!F:F, MATCH(A15, [1]Clients!A:A, 0)), "")
B16: =IFERROR(INDEX([1]Clients!$D:$D, MATCH(A16, [1]Clients!$A:$A, 0)), "") | E16: =IF(OR(D16="",D16=0),"",D16-SUMIFS('Lessons Log'!$E:$E,'Lessons Log'!$C:$C,A16,'Lessons Log'!$D:$D,"*Package*")) | F16: =IFERROR(INDEX([1]Clients!F:F, MATCH(A16, [1]Clients!A:A, 0)), "")
B17: =IFERROR(INDEX([1]Clients!$D:$D, MATCH(A17, [1]Clients!$A:$A, 0)), "") | E17: =IF(OR(D17="",D17=0),"",D17-SUMIFS('Lessons Log'!$E:$E,'Lessons Log'!$C:$C,A17,'Lessons Log'!$D:$D,"*Package*")) | F17: =IFERROR(INDEX([1]Clients!F:F, MATCH(A17, [1]Clients!A:A, 0)), "")
B18: =IFERROR(INDEX([1]Clients!$D:$D, MATCH(A18, [1]Clients!$A:$A, 0)), "") | E18: =IF(OR(D18="",D18=0),"",D18-SUMIFS('Lessons Log'!$E:$E,'Lessons Log'!$C:$C,A18,'Lessons Log'!$D:$D,"*Package*")) | F18: =IFERROR(INDEX([1]Clients!F:F, MATCH(A18, [1]Clients!A:A, 0)), "")
B19: =IFERROR(INDEX([1]Clients!$D:$D, MATCH(A19, [1]Clients!$A:$A, 0)), "") | E19: =IF(OR(D19="",D19=0),"",D19-SUMIFS('Lessons Log'!$E:$E,'Lessons Log'!$C:$C,A19,'Lessons Log'!$D:$D,"*Package*")) | F19: =IFERROR(INDEX([1]Clients!F:F, MATCH(A19, [1]Clients!A:A, 0)), "")
B20: =IFERROR(INDEX([1]Clients!$D:$D, MATCH(A20, [1]Clients!$A:$A, 0)), "") | E20: =IF(OR(D20="",D20=0),"",D20-SUMIFS('Lessons Log'!$E:$E,'Lessons Log'!$C:$C,A20,'Lessons Log'!$D:$D,"*Package*")) | F20: =IFERROR(INDEX([1]Clients!F:F, MATCH(A20, [1]Clients!A:A, 0)), "")
B21: =IFERROR(INDEX([1]Clients!$D:$D, MATCH(A21, [1]Clients!$A:$A, 0)), "") | E21: =IF(OR(D21="",D21=0),"",D21-SUMIFS('Lessons Log'!$E:$E,'Lessons Log'!$C:$C,A21,'Lessons Log'!$D:$D,"*Package*")) | F21: =IFERROR(INDEX([1]Clients!F:F, MATCH(A21, [1]Clients!A:A, 0)), "")
B22: =IFERROR(INDEX([1]Clients!$D:$D, MATCH(A22, [1]Clients!$A:$A, 0)), "") | E22: =IF(OR(D22="",D22=0),"",D22-SUMIFS('Lessons Log'!$E:$E,'Lessons Log'!$C:$C,A22,'Lessons Log'!$D:$D,"*Package*")) | F22: =IFERROR(INDEX([1]Clients!F:F, MATCH(A22, [1]Clients!A:A, 0)), "")
... B1000: =IFERROR(INDEX([1]Clients!$D:$D, MATCH(A1000, [1]Clients!$A:$A, 0)), "") | E1000: =IF(OR(D1000="",D1000=0),"",D1000-SUMIFS('Lessons Log'!$E:$E,'Lessons Log'!$C:$C,A1000,'Lessons Log'!$D:$D,"*Package*")) | F1000: =IFERROR(INDEX([1]Clients!F:F, MATCH(A1000, [1]Clients!A:A, 0)), "")

Sheet Lessons Log
A1: Date | B1: Payments | C1: Client | D1: Lesson Type | E1: Hours | F1: Package Balance | G1: Session ID | H1: Coach Hours | I1: Rate | J1: Notes
D2: =IFERROR(VLOOKUP(C2,'Clients List'!$A:$F,2,FALSE),"") | F2: =IF(OR(C2="",NOT(ISNUMBER(SEARCH("Package",D2)))),"",VLOOKUP(C2,'Clients List'!$A:$F,4,FALSE)-SUMIFS($E$2:$E2,$C$2:$C2,C2,$D$2:$D2,"*Package*")) | G2: =IF(ISNUMBER(SEARCH("Group",D2)),IFERROR("GRP-"&TEXT(IF(ISNUMBER(A2),A2,DATEVALUE(A2)),"yyyymmdd"),""),"" ) | H2: =IF(ISNUMBER(SEARCH("Group",D2)),IF(G2="",E2,IFERROR(E2/COUNTIF($G2:$G6000,G2),E2)),E2) -> 0 | I2: =IFERROR(VLOOKUP(C2,'Clients List'!A:F,6,FALSE),"")
D3: =IFERROR(VLOOKUP(C3,'Clients List'!$A:$F,2,FALSE),"") | F3: =IF(OR(C3="",NOT(ISNUMBER(SEARCH("Package",D3)))),"",VLOOKUP(C3,'Clients List'!$A:$F,4,FALSE)-SUMIFS($E$2:$E3,$C$2:$C3,C3,$D$2:$D3,"*Package*")) | G3: =IF(ISNUMBER(SEARCH("Group",D3)),IFERROR("GRP-"&TEXT(IF(ISNUMBER(A3),A3,DATEVALUE(A3)),"yyyymmdd"),""),"" ) | H3: =IF(ISNUMBER(SEARCH("Group",D3)),IF(G3="",E3,IFERROR(E3/COUNTIF($G2:$G6000,G3),E3)),E3) -> 0 | I3: =IFERROR(VLOOKUP(C3,'Clients List'!A:F,6,FALSE),"")
D4: =IFERROR(VLOOKUP(C4,'Clients List'!$A:$F,2,FALSE),"") | F4: =IF(OR(C4="",NOT(ISNUMBER(SEARCH("Package",D4)))),"",VLOOKUP(C4,'Clients List'!$A:$F,4,FALSE)-SUMIFS($E$2:$E4,$C$2:$C4,C4,$D$2:$D4,"*Package*")) | G4: =IF(ISNUMBER(SEARCH("Group",D4)),IFERROR("GRP-"&TEXT(IF(ISNUMBER(A4),A4,DATEVALUE(A4)),"yyyymmdd"),""),"" ) | H4: =IF(ISNUMBER(SEARCH("Group",D4)),IF(G4="",E4,IFERROR(E4/COUNTIF($G2:$G6000,G4),E4)),E4) -> 0 | I4: =IFERROR(VLOOKUP(C4,'Clients List'!A:F,6,FALSE),"")
D5: =IFERROR(VLOOKUP(C5,'Clients List'!$A:$F,2,FALSE),"") | F5: =IF(OR(C5="",NOT(ISNUMBER(SEARCH("Package",D5)))),"",VLOOKUP(C5,'Clients List'!$A:$F,4,FALSE)-SUMIFS($E$2:$E5,$C$2:$C5,C5,$D$2:$D5,"*Package*")) | G5: =IF(ISNUMBER(SEARCH("Group",D5)),IFERROR("GRP-"&TEXT(IF(ISNUMBER(A5),A5,DATEVALUE(A5)),"yyyymmdd"),""),"" ) | H5: =IF(ISNUMBER(SEARCH("Group",D5)),IF(G5="",E5,IFERROR(E5/COUNTIF($G2:$G6000,G5),E5)),E5) -> 0 | I5: =IFERROR(VLOOKUP(C5,'Clients List'!A:F,6,FALSE),"")
D6: =IFERROR(VLOOKUP(C6,'Clients List'!$A:$F,2,FALSE),"") | F6: =IF(OR(C6="",NOT(ISNUMBER(SEARCH("Package",D6)))),"",VLOOKUP(C6,'Clients List'!$A:$F,4,FALSE)-SUMIFS($E$2:$E6,$C$2:$C6,C6,$D$2:$D6,"*Package*")) | G6: =IF(ISNUMBER(SEARCH("Group",D6)),IFERROR("GRP-"&TEXT(IF(ISNUMBER(A6),A6,DATEVALUE(A6)),"yyyymmdd"),""),"" ) | H6: =IF(ISNUMBER(SEARCH("Group",D6)),IF(G6="",E6,IFERROR(E6/COUNTIF($G2:$G6000,G6),E6)),E6) -> 0 | I6: =IFERROR(VLOOKUP(C6,'Clients List'!A:F,6,FALSE),"")
D7: =IFERROR(VLOOKUP(C7,'Clients List'!$A:$F,2,FALSE),"") | F7: =IF(OR(C7="",NOT(ISNUMBER(SEARCH("Package",D7)))),"",VLOOKUP(C7,'Clients List'!$A:$F,4,FALSE)-SUMIFS($E$2:$E7,$C$2:$C7,C7,$D$2:$D7,"*Package*")) | G7: =IF(ISNUMBER(SEARCH("Group",D7)),IFERROR("GRP-"&TEXT(IF(ISNUMBER(A7),A7,DATEVALUE(A7)),"yyyymmdd"),""),"" ) | H7: =IF(ISNUMBER(SEARCH("Group",D7)),IF(G7="",E7,IFERROR(E7/COUNTIF($G2:$G6000,G7),E7)),E7) -> 0 | I7: =IFERROR(VLOOKUP(C7,'Clients List'!A:F,6,FALSE),"")
D8: =IFERROR(VLOOKUP(C8,'Clients List'!$A:$F,2,FALSE),"") | F8: =IF(OR(C8="",NOT(ISNUMBER(SEARCH("Package",D8)))),"",VLOOKUP(C8,'Clients List'!$A:$F,4,FALSE)-SUMIFS($E$2:$E8,$C$2:$C8,C8,$D$2:$D8,"*Package*")) | G8: =IF(ISNUMBER(SEARCH("Group",D8)),IFERROR("GRP-"&TEXT(IF(ISNUMBER(A8),A8,DATEVALUE(A8)),"yyyymmdd"),""),"" ) | H8: =IF(ISNUMBER(SEARCH("Group",D8)),IF(G8="",E8,IFERROR(E8/COUNTIF($G2:$G6000,G8),E8)),E8) -> 0 | I8: =IFERROR(VLOOKUP(C8,'Clients List'!A:F,6,FALSE),"")
D9: =IFERROR(VLOOKUP(C9,'Clients List'!$A:$F,2,FALSE),"") | F9: =IF(OR(C9="",NOT(ISNUMBER(SEARCH("Package",D9)))),"",VLOOKUP(C9,'Clients List'!$A:$F,4,FALSE)-SUMIFS($E$2:$E9,$C$2:$C9,C9,$D$2:$D9,"*Package*")) | G9: =IF(ISNUMBER(SEARCH("Group",D9)),IFERROR("GRP-"&TEXT(IF(ISNUMBER(A9),A9,DATEVALUE(A9)),"yyyymmdd"),""),"" ) | H9: =IF(ISNUMBER(SEARCH("Group",D9)),IF(G9="",E9,IFERROR(E9/COUNTIF($G2:$G6000,G9),E9)),E9) -> 0 | I9: =IFERROR(VLOOKUP(C9,'Clients List'!A:F,6,FALSE),"")
D10: =IFERROR(VLOOKUP(C10,'Clients List'!$A:$F,2,FALSE),"") | F10: =IF(OR(C10="",NOT(ISNUMBER(SEARCH("Package",D10)))),"",VLOOKUP(C10,'Clients List'!$A:$F,4,FALSE)-SUMIFS($E$2:$E10,$C$2:$C10,C10,$D$2:$D10,"*Package*")) | G10: =IF(ISNUMBER(SEARCH("Group",D10)),IFERROR("GRP-"&TEXT(IF(ISNUMBER(A10),A10,DATEVALUE(A10)),"yyyymmdd"),""),"" ) | H10: =IF(ISNUMBER(SEARCH("Group",D10)),IF(G10="",E10,IFERROR(E10/COUNTIF($G2:$G6000,G10),E10)),E10) -> 0 | I10: =IFERROR(VLOOKUP(C10,'Clients List'!A:F,6,FALSE),"")
D11: =IFERROR(VLOOKUP(C11,'Clients List'!$A:$F,2,FALSE),"") | F11: =IF(OR(C11="",NOT(ISNUMBER(SEARCH("Package",D11)))),"",VLOOKUP(C11,'Clients List'!$A:$F,4,FALSE)-SUMIFS($E$2:$E11,$C$2:$C11,C11,$D$2:$D11,"*Package*")) | G11: =IF(ISNUMBER(SEARCH("Group",D11)),IFERROR("GRP-"&TEXT(IF(ISNUMBER(A11),A11,DATEVALUE(A11)),"yyyymmdd"),""),"" ) | H11: =IF(ISNUMBER(SEARCH("Group",D11)),IF(G11="",E11,IFERROR(E11/COUNTIF($G2:$G6000,G11),E11)),E11) -> 0 | I11: =IFERROR(VLOOKUP(C11,'Clients List'!A:F,6,FALSE),"")
D12: =IFERROR(VLOOKUP(C12,'Clients List'!$A:$F,2,FALSE),"") | F12: =IF(OR(C12="",NOT(ISNUMBER(SEARCH("Package",D12)))),"",VLOOKUP(C12,'Clients List'!$A:$F,4,FALSE)-SUMIFS($E$2:$E12,$C$2:$C12,C12,$D$2:$D12,"*Package*")) | G12: =IF(ISNUMBER(SEARCH("Group",D12)),IFERROR("GRP-"&TEXT(IF(ISNUMBER(A12),A12,DATEVALUE(A12)),"yyyymmdd"),""),"" ) | H12: =IF(ISNUMBER(SEARCH("Group",D12)),IF(G12="",E12,IFERROR(E12/COUNTIF($G2:$G6000,G12),E12)),E12) -> 0 | I12: =IFERROR(VLOOKUP(C12,'Clients List'!A:F,6,FALSE),"")
D13: =IFERROR(VLOOKUP(C13,'Clients List'!$A:$F,2,FALSE),"") | F13: =IF(OR(C13="",NOT(ISNUMBER(SEARCH("Package",D13)))),"",VLOOKUP(C13,'Clients List'!$A:$F,4,FALSE)-SUMIFS($E$2:$E13,$C$2:$C13,C13,$D$2:$D13,"*Package*")) | G13: =IF(ISNUMBER(SEARCH("Group",D13)),IFERROR("GRP-"&TEXT(IF(ISNUMBER(A13),A13,DATEVALUE(A13)),"yyyymmdd"),""),"" ) | H13: =IF(ISNUMBER(SEARCH("Group",D13)),IF(G13="",E13,IFERROR(E13/COUNTIF($G2:$G6000,G13),E13)),E13) -> 0 | I13: =IFERROR(VLOOKUP(C13,'Clients List'!A:F,6,FALSE),"")
D14: =IFERROR(VLOOKUP(C14,'Clients List'!$A:$F,2,FALSE),"") | F14: =IF(OR(C14="",NOT(ISNUMBER(SEARCH("Package",D14)))),"",VLOOKUP(C14,'Clients List'!$A:$F,4,FALSE)-SUMIFS($E$2:$E14,$C$2:$C14,C14,$D$2:$D14,"*Package*")) | G14: =IF(ISNUMBER(SEARCH("Group",D14)),IFERROR("GRP-"&TEXT(IF(ISNUMBER(A14),A14,DATEVALUE(A14)),"yyyymmdd"),""),"" ) | H14: =IF(ISNUMBER(SEARCH("Group",D14)),IF(G14="",E14,IFERROR(E14/COUNTIF($G2:$G6000,G14),E14)),E14) -> 0 | I14: =IFERROR(VLOOKUP(C14,'Clients List'!A:F,6,FALSE),"")
D15: =IFERROR(VLOOKUP(C15,'Clients List'!$A:$F,2,FALSE),"") | F15: =IF(OR(C15="",NOT(ISNUMBER(SEARCH("Package",D15)))),"",VLOOKUP(C15,'Clients List'!$A:$F,4,FALSE)-SUMIFS($E$2:$E15,$C$2:$C15,C15,$D$2:$D15,"*Package*")) | G15: =IF(ISNUMBER(SEARCH("Group",D15)),IFERROR("GRP-"&TEXT(IF(ISNUMBER(A15),A15,DATEVALUE(A15)),"yyyymmdd"),""),"" ) | H15: =IF(ISNUMBER(SEARCH("Group",D15)),IF(G15="",E15,IFERROR(E15/COUNTIF($G2:$G6000,G15),E15)),E15) -> 0 | I15: =IFERROR(VLOOKUP(C15,'Clients List'!A:F,6,FALSE),"")
D16: =IFERROR(VLOOKUP(C16,'Clients List'!$A:$F,2,FALSE),"") | F16: =IF(OR(C16="",NOT(ISNUMBER(SEARCH("Package",D16)))),"",VLOOKUP(C16,'Clients List'!$A:$F,4,FALSE)-SUMIFS($E$2:$E16,$C$2:$C16,C16,$D$2:$D16,"*Package*")) | G16: =IF(ISNUMBER(SEARCH("Group",D16)),IFERROR("GRP-"&TEXT(IF(ISNUMBER(A16),A16,DATEVALUE(A16)),"yyyymmdd"),""),"" ) | H16: =IF(ISNUMBER(SEARCH("Group",D16)),IF(G16="",E16,IFERROR(E16/COUNTIF($G2:$G6000,G16),E16)),E16) -> 0 | I16: =IFERROR(VLOOKUP(C16,'Clients List'!A:F,6,FALSE),"")
D17: =IFERROR(VLOOKUP(C17,'Clients List'!$A:$F,2,FALSE),"") | F17: =IF(OR(C17="",NOT(ISNUMBER(SEARCH("Package",D17)))),"",VLOOKUP(C17,'Clients List'!$A:$F,4,FALSE)-SUMIFS($E$2:$E17,$C$2:$C17,C17,$D$2:$D17,"*Package*")) | G17: =IF(ISNUMBER(SEARCH("Group",D17)),IFERROR("GRP-"&TEXT(IF(ISNUMBER(A17),A17,DATEVALUE(A17)),"yyyymmdd"),""),"" ) | H17: =IF(ISNUMBER(SEARCH("Group",D17)),IF(G17="",E17,IFERROR(E17/COUNTIF($G2:$G6000,G17),E17)),E17) -> 0 | I17: =IFERROR(VLOOKUP(C17,'Clients List'!A:F,6,FALSE),"")
D18: =IFERROR(VLOOKUP(C18,'Clients List'!$A:$F,2,FALSE),"") | F18: =IF(OR(C18="",NOT(ISNUMBER(SEARCH("Package",D18)))),"",VLOOKUP(C18,'Clients List'!$A:$F,4,FALSE)-SUMIFS($E$2:$E18,$C$2:$C18,C18,$D$2:$D18,"*Package*")) | G18: =IF(ISNUMBER(SEARCH("Group",D18)),IFERROR("GRP-"&TEXT(IF(ISNUMBER(A18),A18,DATEVALUE(A18)),"yyyymmdd"),""),"" ) | H18: =IF(ISNUMBER(SEARCH("Group",D18)),IF(G18="",E18,IFERROR(E18/COUNTIF($G2:$G6000,G18),E18)),E18) -> 0 | I18: =IFERROR(VLOOKUP(C18,'Clients List'!A:F,6,FALSE),"")
D19: =IFERROR(VLOOKUP(C19,'Clients List'!$A:$F,2,FALSE),"") | F19: =IF(OR(C19="",NOT(ISNUMBER(SEARCH("Package",D19)))),"",VLOOKUP(C19,'Clients List'!$A:$F,4,FALSE)-SUMIFS($E$2:$E19,$C$2:$C19,C19,$D$2:$D19,"*Package*")) | G19: =IF(ISNUMBER(SEARCH("Group",D19)),IFERROR("GRP-"&TEXT(IF(ISNUMBER(A19),A19,DATEVALUE(A19)),"yyyymmdd"),""),"" ) | H19: =IF(ISNUMBER(SEARCH("Group",D19)),IF(G19="",E19,IFERROR(E19/COUNTIF($G2:$G6000,G19),E19)),E19) -> 0 | I19: =IFERROR(VLOOKUP(C19,'Clients List'!A:F,6,FALSE),"")
D20: =IFERROR(VLOOKUP(C20,'Clients List'!$A:$F,2,FALSE),"") | F20: =IF(OR(C20="",NOT(ISNUMBER(SEARCH("Package",D20)))),"",VLOOKUP(C20,'Clients List'!$A:$F,4,FALSE)-SUMIFS($E$2:$E20,$C$2:$C20,C20,$D$2:$D20,"*Package*")) | G20: =IF(ISNUMBER(SEARCH("Group",D20)),IFERROR("GRP-"&TEXT(IF(ISNUMBER(A20),A20,DATEVALUE(A20)),"yyyymmdd"),""),"" ) | H20: =IF(ISNUMBER(SEARCH("Group",D20)),IF(G20="",E20,IFERROR(E20/COUNTIF($G2:$G6000,G20),E20)),E20) -> 0 | I20: =IFERROR(VLOOKUP(C20,'Clients List'!A:F,6,FALSE),"")
D21: =IFERROR(VLOOKUP(C21,'Clients List'!$A:$F,2,FALSE),"") | F21: =IF(OR(C21="",NOT(ISNUMBER(SEARCH("Package",D21)))),"",VLOOKUP(C21,'Clients List'!$A:$F,4,FALSE)-SUMIFS($E$2:$E21,$C$2:$C21,C21,$D$2:$D21,"*Package*")) | G21: =IF(ISNUMBER(SEARCH("Group",D21)),IFERROR("GRP-"&TEXT(IF(ISNUMBER(A21),A21,DATEVALUE(A21)),"yyyymmdd"),""),"" ) | H21: =IF(ISNUMBER(SEARCH("Group",D21)),IF(G21="",E21,IFERROR(E21/COUNTIF($G2:$G6000,G21),E21)),E21) -> 0 | I21: =IFERROR(VLOOKUP(C21,'Clients List'!A:F,6,FALSE),"")
D22: =IFERROR(VLOOKUP(C22,'Clients List'!$A:$F,2,FALSE),"") | F22: =IF(OR(C22="",NOT(ISNUMBER(SEARCH("Package",D22)))),"",VLOOKUP(C22,'Clients List'!$A:$F,4,FALSE)-SUMIFS($E$2:$E22,$C$2:$C22,C22,$D$2:$D22,"*Package*")) | G22: =IF(ISNUMBER(SEARCH("Group",D22)),IFERROR("GRP-"&TEXT(IF(ISNUMBER(A22),A22,DATEVALUE(A22)),"yyyymmdd"),""),"" ) | H22: =IF(ISNUMBER(SEARCH("Group",D22)),IF(G22="",E22,IFERROR(E22/COUNTIF($G2:$G6000,G22),E22)),E22) -> 0 | I22: =IFERROR(VLOOKUP(C22,'Clients List'!A:F,6,FALSE),"")
D23: =IFERROR(VLOOKUP(C23,'Clients List'!$A:$F,2,FALSE),"") | F23: =IF(OR(C23="",NOT(ISNUMBER(SEARCH("Package",D23)))),"",VLOOKUP(C23,'Clients List'!$A:$F,4,FALSE)-SUMIFS($E$2:$E23,$C$2:$C23,C23,$D$2:$D23,"*Package*")) | G23: =IF(ISNUMBER(SEARCH("Group",D23)),IFERROR("GRP-"&TEXT(IF(ISNUMBER(A23),A23,DATEVALUE(A23)),"yyyymmdd"),""),"" ) | H23: =IF(ISNUMBER(SEARCH("Group",D23)),IF(G23="",E23,IFERROR(E23/COUNTIF($G2:$G6000,G23),E23)),E23) -> 0 | I23: =IFERROR(VLOOKUP(C23,'Clients List'!A:F,6,FALSE),"")
D24: =IFERROR(VLOOKUP(C24,'Clients List'!$A:$F,2,FALSE),"") | F24: =IF(OR(C24="",NOT(ISNUMBER(SEARCH("Package",D24)))),"",VLOOKUP(C24,'Clients List'!$A:$F,4,FALSE)-SUMIFS($E$2:$E24,$C$2:$C24,C24,$D$2:$D24,"*Package*")) | G24: =IF(ISNUMBER(SEARCH("Group",D24)),IFERROR("GRP-"&TEXT(IF(ISNUMBER(A24),A24,DATEVALUE(A24)),"yyyymmdd"),""),"" ) | H24: =IF(ISNUMBER(SEARCH("Group",D24)),IF(G24="",E24,IFERROR(E24/COUNTIF($G2:$G6000,G24),E24)),E24) -> 0 | I24: =IFERROR(VLOOKUP(C24,'Clients List'!A:F,6,FALSE),"")
D25: =IFERROR(VLOOKUP(C25,'Clients List'!$A:$F,2,FALSE),"") | F25: =IF(OR(C25="",NOT(ISNUMBER(SEARCH("Package",D25)))),"",VLOOKUP(C25,'Clients List'!$A:$F,4,FALSE)-SUMIFS($E$2:$E25,$C$2:$C25,C25,$D$2:$D25,"*Package*")) | G25: =IF(ISNUMBER(SEARCH("Group",D25)),IFERROR("GRP-"&TEXT(IF(ISNUMBER(A25),A25,DATEVALUE(A25)),"yyyymmdd"),""),"" ) | H25: =IF(ISNUMBER(SEARCH("Group",D25)),IF(G25="",E25,IFERROR(E25/COUNTIF($G2:$G6000,G25),E25)),E25) -> 0 | I25: =IFERROR(VLOOKUP(C25,'Clients List'!A:F,6,FALSE),"")
D26: =IFERROR(VLOOKUP(C26,'Clients List'!$A:$F,2,FALSE),"") | F26: =IF(OR(C26="",NOT(ISNUMBER(SEARCH("Package",D26)))),"",VLOOKUP(C26,'Clients List'!$A:$F,4,FALSE)-SUMIFS($E$2:$E26,$C$2:$C26,C26,$D$2:$D26,"*Package*")) | G26: =IF(ISNUMBER(SEARCH("Group",D26)),IFERROR("GRP-"&TEXT(IF(ISNUMBER(A26),A26,DATEVALUE(A26)),"yyyymmdd"),""),"" ) | H26: =IF(ISNUMBER(SEARCH("Group",D26)),IF(G26="",E26,IFERROR(E26/COUNTIF($G2:$G6000,G26),E26)),E26) -> 0 | I26: =IFERROR(VLOOKUP(C26,'Clients List'!A:F,6,FALSE),"")
D27: =IFERROR(VLOOKUP(C27,'Clients List'!$A:$F,2,FALSE),"") | F27: =IF(OR(C27="",NOT(ISNUMBER(SEARCH("Package",D27)))),"",VLOOKUP(C27,'Clients List'!$A:$F,4,FALSE)-SUMIFS($E$2:$E27,$C$2:$C27,C27,$D$2:$D27,"*Package*")) | G27: =IF(ISNUMBER(SEARCH("Group",D27)),IFERROR("GRP-"&TEXT(IF(ISNUMBER(A27),A27,DATEVALUE(A27)),"yyyymmdd"),""),"" ) | H27: =IF(ISNUMBER(SEARCH("Group",D27)),IF(G27="",E27,IFERROR(E27/COUNTIF($G2:$G6000,G27),E27)),E27) -> 0 | I27: =IFERROR(VLOOKUP(C27,'Clients List'!A:F,6,FALSE),"")
D28: =IFERROR(VLOOKUP(C28,'Clients List'!$A:$F,2,FALSE),"") | F28: =IF(OR(C28="",NOT(ISNUMBER(SEARCH("Package",D28)))),"",VLOOKUP(C28,'Clients List'!$A:$F,4,FALSE)-SUMIFS($E$2:$E28,$C$2:$C28,C28,$D$2:$D28,"*Package*")) | G28: =IF(ISNUMBER(SEARCH("Group",D28)),IFERROR("GRP-"&TEXT(IF(ISNUMBER(A28),A28,DATEVALUE(A28)),"yyyymmdd"),""),"" ) | H28: =IF(ISNUMBER(SEARCH("Group",D28)),IF(G28="",E28,IFERROR(E28/COUNTIF($G2:$G6000,G28),E28)),E28) -> 0 | I28: =IFERROR(VLOOKUP(C28,'Clients List'!A:F,6,FALSE),"")
D29: =IFERROR(VLOOKUP(C29,'Clients List'!$A:$F,2,FALSE),"") | F29: =IF(OR(C29="",NOT(ISNUMBER(SEARCH("Package",D29)))),"",VLOOKUP(C29,'Clients List'!$A:$F,4,FALSE)-SUMIFS($E$2:$E29,$C$2:$C29,C29,$D$2:$D29,"*Package*")) | G29: =IF(ISNUMBER(SEARCH("Group",D29)),IFERROR("GRP-"&TEXT(IF(ISNUMBER(A29),A29,DATEVALUE(A29)),"yyyymmdd"),""),"" ) | H29: =IF(ISNUMBER(SEARCH("Group",D29)),IF(G29="",E29,IFERROR(E29/COUNTIF($G2:$G6000,G29),E29)),E29) -> 0 | I29: =IFERROR(VLOOKUP(C29,'Clients List'!A:F,6,FALSE),"")
D30: =IFERROR(VLOOKUP(C30,'Clients List'!$A:$F,2,FALSE),"") | F30: =IF(OR(C30="",NOT(ISNUMBER(SEARCH("Package",D30)))),"",VLOOKUP(C30,'Clients List'!$A:$F,4,FALSE)-SUMIFS($E$2:$E30,$C$2:$C30,C30,$D$2:$D30,"*Package*")) | G30: =IF(ISNUMBER(SEARCH("Group",D30)),IFERROR("GRP-"&TEXT(IF(ISNUMBER(A30),A30,DATEVALUE(A30)),"yyyymmdd"),""),"" ) | H30: =IF(ISNUMBER(SEARCH("Group",D30)),IF(G30="",E30,IFERROR(E30/COUNTIF($G2:$G6000,G30),E30)),E30) -> 0 | I30: =IFERROR(VLOOKUP(C30,'Clients List'!A:F,6,FALSE),"")
D31: =IFERROR(VLOOKUP(C31,'Clients List'!$A:$F,2,FALSE),"") | F31: =IF(OR(C31="",NOT(ISNUMBER(SEARCH("Package",D31)))),"",VLOOKUP(C31,'Clients List'!$A:$F,4,FALSE)-SUMIFS($E$2:$E31,$C$2:$C31,C31,$D$2:$D31,"*Package*")) | G31: =IF(ISNUMBER(SEARCH("Group",D31)),IFERROR("GRP-"&TEXT(IF(ISNUMBER(A31),A31,DATEVALUE(A31)),"yyyymmdd"),""),"" ) | H31: =IF(ISNUMBER(SEARCH("Group",D31)),IF(G31="",E31,IFERROR(E31/COUNTIF($G2:$G6000,G31),E31)),E31) -> 0 | I31: =IFERROR(VLOOKUP(C31,'Clients List'!A:F,6,FALSE),"")
D32: =IFERROR(VLOOKUP(C32,'Clients List'!$A:$F,2,FALSE),"") | F32: =IF(OR(C32="",NOT(ISNUMBER(SEARCH("Package",D32)))),"",VLOOKUP(C32,'Clients List'!$A:$F,4,FALSE)-SUMIFS($E$2:$E32,$C$2:$C32,C32,$D$2:$D32,"*Package*")) | G32: =IF(ISNUMBER(SEARCH("Group",D32)),IFERROR("GRP-"&TEXT(IF(ISNUMBER(A32),A32,DATEVALUE(A32)),"yyyymmdd"),""),"" ) | H32: =IF(ISNUMBER(SEARCH("Group",D32)),IF(G32="",E32,IFERROR(E32/COUNTIF($G2:$G6000,G32),E32)),E32) -> 0 | I32: =IFERROR(VLOOKUP(C32,'Clients List'!A:F,6,FALSE),"")
D33: =IFERROR(VLOOKUP(C33,'Clients List'!$A:$F,2,FALSE),"") | F33: =IF(OR(C33="",NOT(ISNUMBER(SEARCH("Package",D33)))),"",VLOOKUP(C33,'Clients List'!$A:$F,4,FALSE)-SUMIFS($E$2:$E33,$C$2:$C33,C33,$D$2:$D33,"*Package*")) | G33: =IF(ISNUMBER(SEARCH("Group",D33)),IFERROR("GRP-"&TEXT(IF(ISNUMBER(A33),A33,DATEVALUE(A33)),"yyyymmdd"),""),"" ) | H33: =IF(ISNUMBER(SEARCH("Group",D33)),IF(G33="",E33,IFERROR(E33/COUNTIF($G2:$G6000,G33),E33)),E33) -> 0 | I33: =IFERROR(VLOOKUP(C33,'Clients List'!A:F,6,FALSE),"")
D34: =IFERROR(VLOOKUP(C34,'Clients List'!$A:$F,2,FALSE),"") | F34: =IF(OR(C34="",NOT(ISNUMBER(SEARCH("Package",D34)))),"",VLOOKUP(C34,'Clients List'!$A:$F,4,FALSE)-SUMIFS($E$2:$E34,$C$2:$C34,C34,$D$2:$D34,"*Package*")) | G34: =IF(ISNUMBER(SEARCH("Group",D34)),IFERROR("GRP-"&TEXT(IF(ISNUMBER(A34),A34,DATEVALUE(A34)),"yyyymmdd"),""),"" ) | H34: =IF(ISNUMBER(SEARCH("Group",D34)),IF(G34="",E34,IFERROR(E34/COUNTIF($G2:$G6000,G34),E34)),E34) -> 0 | I34: =IFERROR(VLOOKUP(C34,'Clients List'!A:F,6,FALSE),"")
D35: =IFERROR(VLOOKUP(C35,'Clients List'!$A:$F,2,FALSE),"") | F35: =IF(OR(C35="",NOT(ISNUMBER(SEARCH("Package",D35)))),"",VLOOKUP(C35,'Clients List'!$A:$F,4,FALSE)-SUMIFS($E$2:$E35,$C$2:$C35,C35,$D$2:$D35,"*Package*")) | G35: =IF(ISNUMBER(SEARCH("Group",D35)),IFERROR("GRP-"&TEXT(IF(ISNUMBER(A35),A35,DATEVALUE(A35)),"yyyymmdd"),""),"" ) | H35: =IF(ISNUMBER(SEARCH("Group",D35)),IF(G35="",E35,IFERROR(E35/COUNTIF($G2:$G6000,G35),E35)),E35) -> 0 | I35: =IFERROR(VLOOKUP(C35,'Clients List'!A:F,6,FALSE),"")
D36: =IFERROR(VLOOKUP(C36,'Clients List'!$A:$F,2,FALSE),"") | F36: =IF(OR(C36="",NOT(ISNUMBER(SEARCH("Package",D36)))),"",VLOOKUP(C36,'Clients List'!$A:$F,4,FALSE)-SUMIFS($E$2:$E36,$C$2:$C36,C36,$D$2:$D36,"*Package*")) | G36: =IF(ISNUMBER(SEARCH("Group",D36)),IFERROR("GRP-"&TEXT(IF(ISNUMBER(A36),A36,DATEVALUE(A36)),"yyyymmdd"),""),"" ) | H36: =IF(ISNUMBER(SEARCH("Group",D36)),IF(G36="",E36,IFERROR(E36/COUNTIF($G2:$G6000,G36),E36)),E36) -> 0 | I36: =IFERROR(VLOOKUP(C36,'Clients List'!A:F,6,FALSE),"")
D37: =IFERROR(VLOOKUP(C37,'Clients List'!$A:$F,2,FALSE),"") | F37: =IF(OR(C37="",NOT(ISNUMBER(SEARCH("Package",D37)))),"",VLOOKUP(C37,'Clients List'!$A:$F,4,FALSE)-SUMIFS($E$2:$E37,$C$2:$C37,C37,$D$2:$D37,"*Package*")) | G37: =IF(ISNUMBER(SEARCH("Group",D37)),IFERROR("GRP-"&TEXT(IF(ISNUMBER(A37),A37,DATEVALUE(A37)),"yyyymmdd"),""),"" ) | H37: =IF(ISNUMBER(SEARCH("Group",D37)),IF(G37="",E37,IFERROR(E37/COUNTIF($G2:$G6000,G37),E37)),E37) -> 0 | I37: =IFERROR(VLOOKUP(C37,'Clients List'!A:F,6,FALSE),"")
D38: =IFERROR(VLOOKUP(C38,'Clients List'!$A:$F,2,FALSE),"") | F38: =IF(OR(C38="",NOT(ISNUMBER(SEARCH("Package",D38)))),"",VLOOKUP(C38,'Clients List'!$A:$F,4,FALSE)-SUMIFS($E$2:$E38,$C$2:$C38,C38,$D$2:$D38,"*Package*")) | G38: =IF(ISNUMBER(SEARCH("Group",D38)),IFERROR("GRP-"&TEXT(IF(ISNUMBER(A38),A38,DATEVALUE(A38)),"yyyymmdd"),""),"" ) | H38: =IF(ISNUMBER(SEARCH("Group",D38)),IF(G38="",E38,IFERROR(E38/COUNTIF($G2:$G6000,G38),E38)),E38) -> 0 | I38: =IFERROR(VLOOKUP(C38,'Clients List'!A:F,6,FALSE),"")
D39: =IFERROR(VLOOKUP(C39,'Clients List'!$A:$F,2,FALSE),"") | F39: =IF(OR(C39="",NOT(ISNUMBER(SEARCH("Package",D39)))),"",VLOOKUP(C39,'Clients List'!$A:$F,4,FALSE)-SUMIFS($E$2:$E39,$C$2:$C39,C39,$D$2:$D39,"*Package*")) | G39: =IF(ISNUMBER(SEARCH("Group",D39)),IFERROR("GRP-"&TEXT(IF(ISNUMBER(A39),A39,DATEVALUE(A39)),"yyyymmdd"),""),"" ) | H39: =IF(ISNUMBER(SEARCH("Group",D39)),IF(G39="",E39,IFERROR(E39/COUNTIF($G2:$G6000,G39),E39)),E39) -> 0 | I39: =IFERROR(VLOOKUP(C39,'Clients List'!A:F,6,FALSE),"")
D40: =IFERROR(VLOOKUP(C40,'Clients List'!$A:$F,2,FALSE),"") | F40: =IF(OR(C40="",NOT(ISNUMBER(SEARCH("Package",D40)))),"",VLOOKUP(C40,'Clients List'!$A:$F,4,FALSE)-SUMIFS($E$2:$E40,$C$2:$C40,C40,$D$2:$D40,"*Package*")) | G40: =IF(ISNUMBER(SEARCH("Group",D40)),IFERROR("GRP-"&TEXT(IF(ISNUMBER(A40),A40,DATEVALUE(A40)),"yyyymmdd"),""),"" ) | H40: =IF(ISNUMBER(SEARCH("Group",D40)),IF(G40="",E40,IFERROR(E40/COUNTIF($G2:$G6000,G40),E40)),E40) -> 0 | I40: =IFERROR(VLOOKUP(C40,'Clients List'!A:F,6,FALSE),"")
...

Sheet Revenue
A1: Revenue (Lesson Hours × Client Default Price) – 2026
A3: Month | B3: Total Lesson Hours | C3: Calculated Revenue | D3: Expances | E3: Net Profit
A4: January 2026 | B4: =SUMPRODUCT(--ISNUMBER('Lessons Log'!$A$2:$A$6000),--(YEAR('Lessons Log'!$A$2:$A$6000)=2026),--(MONTH('Lessons Log'!$A$2:$A$6000)=1),'Lessons Log'!$H$2:$H$6000) -> 0 | C4: =SUMPRODUCT(--ISNUMBER('Lessons Log'!$A$2:$A$6000),--(YEAR('Lessons Log'!$A$2:$A$6000)=2026),--(MONTH('Lessons Log'!$A$2:$A$6000)=1),'Lessons Log'!$E$2:$E$6000,'Lessons Log'!$I$2:$I$6000) -> 0
A5: February 2026 | B5: =SUMPRODUCT(--ISNUMBER('Lessons Log'!$A$2:$A$6000),--(YEAR('Lessons Log'!$A$2:$A$6000)=2026),--(MONTH('Lessons Log'!$A$2:$A$6000)=2),'Lessons Log'!$H$2:$H$6000) -> 0 | C5: =SUMPRODUCT(--ISNUMBER('Lessons Log'!$A$2:$A$6000),--(YEAR('Lessons Log'!$A$2:$A$6000)=2026),--(MONTH('Lessons Log'!$A$2:$A$6000)=2),'Lessons Log'!$E$2:$E$6000,'Lessons Log'!$I$2:$I$6000) -> 0
A6: March 2026 | B6: =SUMPRODUCT(--ISNUMBER('Lessons Log'!$A$2:$A$6000),--(YEAR('Lessons Log'!$A$2:$A$6000)=2026),--(MONTH('Lessons Log'!$A$2:$A$6000)=3),'Lessons Log'!$H$2:$H$6000) -> 0 | C6: =SUMPRODUCT(--ISNUMBER('Lessons Log'!$A$2:$A$6000),--(YEAR('Lessons Log'!$A$2:$A$6000)=2026),--(MONTH('Lessons Log'!$A$2:$A$6000)=3),'Lessons Log'!$E$2:$E$6000,'Lessons Log'!$I$2:$I$6000) -> 0
A7: April 2026 | B7: =SUMPRODUCT(--ISNUMBER('Lessons Log'!$A$2:$A$6000),--(YEAR('Lessons Log'!$A$2:$A$6000)=2026),--(MONTH('Lessons Log'!$A$2:$A$6000)=4),'Lessons Log'!$H$2:$H$6000) -> 0 | C7: =SUMPRODUCT(--ISNUMBER('Lessons Log'!$A$2:$A$6000),--(YEAR('Lessons Log'!$A$2:$A$6000)=2026),--(MONTH('Lessons Log'!$A$2:$A$6000)=4),'Lessons Log'!$E$2:$E$6000,'Lessons Log'!$I$2:$I$6000) -> 0
A8: May 2026 | B8: =SUMPRODUCT(--ISNUMBER('Lessons Log'!$A$2:$A$6000),--(YEAR('Lessons Log'!$A$2:$A$6000)=2026),--(MONTH('Lessons Log'!$A$2:$A$6000)=5),'Lessons Log'!$H$2:$H$6000) -> 0 | C8: =SUMPRODUCT(--ISNUMBER('Lessons Log'!$A$2:$A$6000),--(YEAR('Lessons Log'!$A$2:$A$6000)=2026),--(MONTH('Lessons Log'!$A$2:$A$6000)=5),'Lessons Log'!$E$2:$E$6000,'Lessons Log'!$I$2:$I$6000) -> 0
A9: June 2026 | B9: =SUMPRODUCT(--ISNUMBER('Lessons Log'!$A$2:$A$6000),--(YEAR('Lessons Log'!$A$2:$A$6000)=2026),--(MONTH('Lessons Log'!$A$2:$A$6000)=6),'Lessons Log'!$H$2:$H$6000) -> 0 | C9: =SUMPRODUCT(--ISNUMBER('Lessons Log'!$A$2:$A$6000),--(YEAR('Lessons Log'!$A$2:$A$6000)=2026),--(MONTH('Lessons Log'!$A$2:$A$6000)=6),'Lessons Log'!$E$2:$E$6000,'Lessons Log'!$I$2:$I$6000) -> 0
A10: July 2026 | B10: =SUMPRODUCT(--ISNUMBER('Lessons Log'!$A$2:$A$6000),--(YEAR('Lessons Log'!$A$2:$A$6000)=2026),--(MONTH('Lessons Log'!$A$2:$A$6000)=7),'Lessons Log'!$H$2:$H$6000) -> 0 | C10: =SUMPRODUCT(--ISNUMBER('Lessons Log'!$A$2:$A$6000),--(YEAR('Lessons Log'!$A$2:$A$6000)=2026),--(MONTH('Lessons Log'!$A$2:$A$6000)=7),'Lessons Log'!$E$2:$E$6000,'Lessons Log'!$I$2:$I$6000) -> 0
A11: August 2026 | B11: =SUMPRODUCT(--ISNUMBER('Lessons Log'!$A$2:$A$6000),--(YEAR('Lessons Log'!$A$2:$A$6000)=2026),--(MONTH('Lessons Log'!$A$2:$A$6000)=8),'Lessons Log'!$H$2:$H$6000) -> 0 | C11: =SUMPRODUCT(--ISNUMBER('Lessons Log'!$A$2:$A$6000),--(YEAR('Lessons Log'!$A$2:$A$6000)=2026),--(MONTH('Lessons Log'!$A$2:$A$6000)=8),'Lessons Log'!$E$2:$E$6000,'Lessons Log'!$I$2:$I$6000) -> 0
A12: September 2026 | B12: =SUMPRODUCT(--ISNUMBER('Lessons Log'!$A$2:$A$6000),--(YEAR('Lessons Log'!$A$2:$A$6000)=2026),--(MONTH('Lessons Log'!$A$2:$A$6000)=9),'Lessons Log'!$H$2:$H$6000) -> 0 | C12: =SUMPRODUCT(--ISNUMBER('Lessons Log'!$A$2:$A$6000),--(YEAR('Lessons Log'!$A$2:$A$6000)=2026),--(MONTH('Lessons Log'!$A$2:$A$6000)=9),'Lessons Log'!$E$2:$E$6000,'Lessons Log'!$I$2:$I$6000) -> 0
A13: October 2026 | B13: =SUMPRODUCT(--ISNUMBER('Lessons Log'!$A$2:$A$6000),--(YEAR('Lessons Log'!$A$2:$A$6000)=2026),--(MONTH('Lessons Log'!$A$2:$A$6000)=10),'Lessons Log'!$H$2:$H$6000) -> 0 | C13: =SUMPRODUCT(--ISNUMBER('Lessons Log'!$A$2:$A$6000),--(YEAR('Lessons Log'!$A$2:$A$6000)=2026),--(MONTH('Lessons Log'!$A$2:$A$6000)=10),'Lessons Log'!$E$2:$E$6000,'Lessons Log'!$I$2:$I$6000) -> 0
A14: November 2026 | B14: =SUMPRODUCT(--ISNUMBER('Lessons Log'!$A$2:$A$6000),--(YEAR('Lessons Log'!$A$2:$A$6000)=2026),--(MONTH('Lessons Log'!$A$2:$A$6000)=11),'Lessons Log'!$H$2:$H$6000) -> 0 | C14: =SUMPRODUCT(--ISNUMBER('Lessons Log'!$A$2:$A$6000),--(YEAR('Lessons Log'!$A$2:$A$6000)=2026),--(MONTH('Lessons Log'!$A$2:$A$6000)=11),'Lessons Log'!$E$2:$E$6000,'Lessons Log'!$I$2:$I$6000) -> 0
A15: December 2026 | B15: =SUMPRODUCT(--ISNUMBER('Lessons Log'!$A$2:$A$6000),--(YEAR('Lessons Log'!$A$2:$A$6000)=2026),--(MONTH('Lessons Log'!$A$2:$A$6000)=12),'Lessons Log'!$H$2:$H$6000) -> 0 | C15: =SUMPRODUCT(--ISNUMBER('Lessons Log'!$A$2:$A$6000),--(YEAR('Lessons Log'!$A$2:$A$6000)=2026),--(MONTH('Lessons Log'!$A$2:$A$6000)=12),'Lessons Log'!$E$2:$E$6000,'Lessons Log'!$I$2:$I$6000) -> 0
A16: TOTAL 2026 | B16: =SUM(B4:B15) -> 0 | C16: =SUM(C4:C15) -> 0 | D16: =SUM(D4:D15) -> 0 | E16: =C16-D16 -> 0

Sheet ValidationLists
A1: Private Lesson $120
A2: Semi Lesson $140
A3: Group Lesson $50
A4: Package Private Lesson $110
A5: Package Semi Lesson $125
A6: Package Group Lesson $40
A7: Custom Private Lesson
A8: Custom Semi Lesson
A9: Custom Group Lesson
A10: Custom Package Private Lesson
A11: Custom Package Semi Lesson
A12: Custom Package Group Lesson
... A14: Custom Tennis Camp
